Workbook
Name v: '[1]Website sales'!#REF!

Sheet Annual fee sales breakup - SAS
M1: 638577.5 | N1: 626851
M2: =SUM(M6:M393) | N2: =SUM(N6:N393)
M3: =+M1-M2 | N3: =+N1-N2
L4: =SUM(L6:L393) | M4: May | O4: Feb - April
A5: S.No | B5: Receipt Date | C5: School Name | D5: Enrollment NO | E5: Delivery status | F5: Student Name | G5: Description | H5: Language of Book | I5: Grade | J5: Receipt No | K5: Fee Type | L5: Total | M5: Book Sales | N5: Uniform Sale | O5: Book Sales | P5: Uniform Sale | Q5: Services to given
A6: 1 | B6: 46098 | C6: SAS BP | D6: SC260407 | E6: #N/A | F6: Ivan Prince | G6: SAS BP LKG MAGIC BOX BOYS | I6: LKG | L6: 11000 | M6: =+SUMIFS('[1]Annual fee sales'!$V:$V,'[1]Annual fee sales'!$L:$L,'Annual fee sales breakup - SAS'!$M$5,'[1]Annual fee sales'!$G:$G,'Annual fee sales breakup - SAS'!F6) | N6: =+SUMIFS('[1]Annual fee sales'!$V:$V,'[1]Annual fee sales'!$L:$L,'Annual fee sales breakup - SAS'!$N$5,'[1]Annual fee sales'!$G:$G,'Annual fee sales breakup - SAS'!F6) | O6: 0 | P6: 0 | Q6: =+L6-M6-N6-O6-P6
A7: =+A6+1 | B7: 46098 | C7: SAS BP | D7: SC260267 | E7: #N/A | F7: Devansh Yadav Addu | G7: SAS BP LKG MAGIC BOX BOYS | I7: LKG | L7: 11000 | M7: =+SUMIFS('[1]Annual fee sales'!$V:$V,'[1]Annual fee sales'!$L:$L,'Annual fee sales breakup - SAS'!$M$5,'[1]Annual fee sales'!$G:$G,'Annual fee sales breakup - SAS'!F7) | N7: =+SUMIFS('[1]Annual fee sales'!$V:$V,'[1]Annual fee sales'!$L:$L,'Annual fee sales breakup - SAS'!$N$5,'[1]Annual fee sales'!$G:$G,'Annual fee sales breakup - SAS'!F7) | O7: 0 | P7: 0 | Q7: =+L7-M7-N7-O7-P7
A8: =+A7+1 | B8: 46098 | C8: SAS BP | D8: 26BP0558 | E8: #N/A | F8: DANDA ADHVITHA REDDY | G8: SAS BP LKG MAGIC BOX GIRLS | I8: LKG | L8: 11000 | M8: =+SUMIFS('[1]Annual fee sales'!$V:$V,'[1]Annual fee sales'!$L:$L,'Annual fee sales breakup - SAS'!$M$5,'[1]Annual fee sales'!$G:$G,'Annual fee sales breakup - SAS'!F8) | N8: =+SUMIFS('[1]Annual fee sales'!$V:$V,'[1]Annual fee sales'!$L:$L,'Annual fee sales breakup - SAS'!$N$5,'[1]Annual fee sales'!$G:$G,'Annual fee sales breakup - SAS'!F8) | O8: 0 | P8: 0 | Q8: =+L8-M8-N8-O8-P8
A9: =+A8+1 | B9: 46098 | C9: SAS BP | D9: SC260076 | E9: #N/A | F9: Yuvika Reddy Musani | G9: SAS BP UKG MAGIC BOX GIRLS | I9: UKG | L9: 11000 | M9: =+SUMIFS('[1]Annual fee sales'!$V:$V,'[1]Annual fee sales'!$L:$L,'Annual fee sales breakup - SAS'!$M$5,'[1]Annual fee sales'!$G:$G,'Annual fee sales breakup - SAS'!F9) | N9: =+SUMIFS('[1]Annual fee sales'!$V:$V,'[1]Annual fee sales'!$L:$L,'Annual fee sales breakup - SAS'!$N$5,'[1]Annual fee sales'!$G:$G,'Annual fee sales breakup - SAS'!F9) | O9: 0 | P9: 0 | Q9: =+L9-M9-N9-O9-P9
A10: =+A9+1 | B10: 46099 | C10: SAS BP | D10: SC260174 | E10: #N/A | F10: Eavanshi Bommala | G10: SAS BP LKG MAGIC BOX GIRLS | I10: LKG | L10: 11000 | M10: =+SUMIFS('[1]Annual fee sales'!$V:$V,'[1]Annual fee sales'!$L:$L,'Annual fee sales breakup - SAS'!$M$5,'[1]Annual fee sales'!$G:$G,'Annual fee sales breakup - SAS'!F10) | N10: =+SUMIFS('[1]Annual fee sales'!$V:$V,'[1]Annual fee sales'!$L:$L,'Annual fee sales breakup - SAS'!$N$5,'[1]Annual fee sales'!$G:$G,'Annual fee sales breakup - SAS'!F10) | O10: 0 | P10: 0 | Q10: =+L10-M10-N10-O10-P10
A11: =+A10+1 | B11: 46099 | C11: SAS BP | D11: SC260132 | E11: #N/A | F11: Shreya L S | G11: SAS BP NURSERY MAGIC BOX GIRLS | I11: Nursery | L11: 11000 | M11: =+SUMIFS('[1]Annual fee sales'!$V:$V,'[1]Annual fee sales'!$L:$L,'Annual fee sales breakup - SAS'!$M$5,'[1]Annual fee sales'!$G:$G,'Annual fee sales breakup - SAS'!F11) | N11: =+SUMIFS('[1]Annual fee sales'!$V:$V,'[1]Annual fee sales'!$L:$L,'Annual fee sales breakup - SAS'!$N$5,'[1]Annual fee sales'!$G:$G,'Annual fee sales breakup - SAS'!F11) | O11: 0 | P11: 0 | Q11: =+L11-M11-N11-O11-P11
A12: =+A11+1 | B12: 46099 | C12: SAS BP | D12: SC260092 | E12: #N/A | F12: Sushrut Saleel Limaye | G12: SAS BP UKG MAGIC BOX BOYS | I12: UKG | L12: 11000 | M12: =+SUMIFS('[1]Annual fee sales'!$V:$V,'[1]Annual fee sales'!$L:$L,'Annual fee sales breakup - SAS'!$M$5,'[1]Annual fee sales'!$G:$G,'Annual fee sales breakup - SAS'!F12) | N12: =+SUMIFS('[1]Annual fee sales'!$V:$V,'[1]Annual fee sales'!$L:$L,'Annual fee sales breakup - SAS'!$N$5,'[1]Annual fee sales'!$G:$G,'Annual fee sales breakup - SAS'!F12) | O12: 0 | P12: 0 | Q12: =+L12-M12-N12-O12-P12
A13: =+A12+1 | B13: 46099 | C13: SAS BP | D13: SC260145 | E13: #N/A | F13: Atharv Garipally | G13: SAS BP UKG MAGIC BOX BOYS | I13: UKG | L13: 11000 | M13: =+SUMIFS('[1]Annual fee sales'!$V:$V,'[1]Annual fee sales'!$L:$L,'Annual fee sales breakup - SAS'!$M$5,'[1]Annual fee sales'!$G:$G,'Annual fee sales breakup - SAS'!F13) | N13: =+SUMIFS('[1]Annual fee sales'!$V:$V,'[1]Annual fee sales'!$L:$L,'Annual fee sales breakup - SAS'!$N$5,'[1]Annual fee sales'!$G:$G,'Annual fee sales breakup - SAS'!F13) | O13: 0 | P13: 0 | Q13: =+L13-M13-N13-O13-P13
A14: =+A13+1 | B14: 46099 | C14: SAS BP | D14: SC260081 | E14: #N/A | F14: Purvansh Nelly | G14: SAS BP UKG MAGIC BOX BOYS | I14: UKG | L14: 11000 | M14: =+SUMIFS('[1]Annual fee sales'!$V:$V,'[1]Annual fee sales'!$L:$L,'Annual fee sales breakup - SAS'!$M$5,'[1]Annual fee sales'!$G:$G,'Annual fee sales breakup - SAS'!F14) | N14: =+SUMIFS('[1]Annual fee sales'!$V:$V,'[1]Annual fee sales'!$L:$L,'Annual fee sales breakup - SAS'!$N$5,'[1]Annual fee sales'!$G:$G,'Annual fee sales breakup - SAS'!F14) | O14: 0 | P14: 0 | Q14: =+L14-M14-N14-O14-P14
A15: =+A14+1 | B15: 46100 | C15: SAS BP | D15: SC260122 | E15: #N/A | F15: Hanzala Arham Mohammad - 1 | G15: SAS BP GRADE 1 MAGIC BOX BOYS | I15: Grade 1 | L15: 16500 | M15: =+SUMIFS('[1]Annual fee sales'!$V:$V,'[1]Annual fee sales'!$L:$L,'Annual fee sales breakup - SAS'!$M$5,'[1]Annual fee sales'!$G:$G,'Annual fee sales breakup - SAS'!F15) | N15: =+SUMIFS('[1]Annual fee sales'!$V:$V,'[1]Annual fee sales'!$L:$L,'Annual fee sales breakup - SAS'!$N$5,'[1]Annual fee sales'!$G:$G,'Annual fee sales breakup - SAS'!F15) | O15: 0 | P15: 0 | Q15: =+L15-M15-N15-O15-P15
A16: =+A15+1 | B16: 46100 | C16: SAS BP | D16: 26BP0532 | E16: #N/A | F16: RIYANSH DIGIJARLA | G16: SAS BP GRADE 1 MAGIC BOX BOYS | I16: Grade 1 | L16: 16500 | M16: =+SUMIFS('[1]Annual fee sales'!$V:$V,'[1]Annual fee sales'!$L:$L,'Annual fee sales breakup - SAS'!$M$5,'[1]Annual fee sales'!$G:$G,'Annual fee sales breakup - SAS'!F16) | N16: =+SUMIFS('[1]Annual fee sales'!$V:$V,'[1]Annual fee sales'!$L:$L,'Annual fee sales breakup - SAS'!$N$5,'[1]Annual fee sales'!$G:$G,'Annual fee sales breakup - SAS'!F16) | O16: 0 | P16: 0 | Q16: =+L16-M16-N16-O16-P16
A17: =+A16+1 | B17: 46100 | C17: SAS BP | D17: SC260147 | E17: #N/A | F17: Kopparapu Sri Dhruti | G17: SAS BP GRADE 1 MAGIC BOX GIRLS | I17: Grade 1 | L17: 16500 | M17: =+SUMIFS('[1]Annual fee sales'!$V:$V,'[1]Annual fee sales'!$L:$L,'Annual fee sales breakup - SAS'!$M$5,'[1]Annual fee sales'!$G:$G,'Annual fee sales breakup - SAS'!F17) | N17: =+SUMIFS('[1]Annual fee sales'!$V:$V,'[1]Annual fee sales'!$L:$L,'Annual fee sales breakup - SAS'!$N$5,'[1]Annual fee sales'!$G:$G,'Annual fee sales breakup - SAS'!F17) | O17: 0 | P17: 0 | Q17: =+L17-M17-N17-O17-P17
A18: =+A17+1 | B18: 46100 | C18: SAS BP | D18: SC260488 | E18: #N/A | F18: Rushika Reddy Gadikoyya | G18: SAS BP GRADE 1 MAGIC BOX GIRLS | I18: Grade 1 | L18: 16500 | M18: =+SUMIFS('[1]Annual fee sales'!$V:$V,'[1]Annual fee sales'!$L:$L,'Annual fee sales breakup - SAS'!$M$5,'[1]Annual fee sales'!$G:$G,'Annual fee sales breakup - SAS'!F18) | N18: =+SUMIFS('[1]Annual fee sales'!$V:$V,'[1]Annual fee sales'!$L:$L,'Annual fee sales breakup - SAS'!$N$5,'[1]Annual fee sales'!$G:$G,'Annual fee sales breakup - SAS'!F18) | O18: 0 | P18: 0 | Q18: =+L18-M18-N18-O18-P18
... A79: =+A78+1 | B79: 46106 | C79: SAS BP | D79: SC260470 | E79: #N/A | F79: Nivaan Varma | G79: SAS BP GRADE 3 MAGIC BOX BOYS | I79: Grade 3 | L79: 16500 | M79: =+SUMIFS('[1]Annual fee sales'!$V:$V,'[1]Annual fee sales'!$L:$L,'Annual fee sales breakup - SAS'!$M$5,'[1]Annual fee sales'!$G:$G,'Annual fee sales breakup - SAS'!F79) | N79: =+SUMIFS('[1]Annual fee sales'!$V:$V,'[1]Annual fee sales'!$L:$L,'Annual fee sales breakup - SAS'!$N$5,'[1]Annual fee sales'!$G:$G,'Annual fee sales breakup - SAS'!F79) | O79: 0 | P79: 0 | Q79: =+L79-M79-N79-O79-P79
A80: =+A79+1 | B80: 46106 | C80: SAS BP | D80: SC260059 | E80: Delivered | F80: Ashrith Ranga Reddy Panyala | G80: SAS BP GRADE 3 MAGIC BOX BOYS | H80: SAS Suchitra Grade 3 BookkitTelugu 2nd Lan Hin 3rd Lan | I80: Grade 3 | L80: 16500 | M80: =+SUMIFS('[1]Annual fee sales'!$V:$V,'[1]Annual fee sales'!$L:$L,'Annual fee sales breakup - SAS'!$M$5,'[1]Annual fee sales'!$G:$G,'Annual fee sales breakup - SAS'!F80) | N80: =+SUMIFS('[1]Annual fee sales'!$V:$V,'[1]Annual fee sales'!$L:$L,'Annual fee sales breakup - SAS'!$N$5,'[1]Annual fee sales'!$G:$G,'Annual fee sales breakup - SAS'!F80) | O80: 8231 | P80: 0 | Q80: =+L80-M80-N80-O80-P80
A81: =+A80+1 | B81: 46106 | C81: SAS BP | D81: SC260062 | E81: #N/A | F81: Sanjay Peram - 1 | G81: SAS BP GRADE 3 MAGIC BOX BOYS | I81: Grade 3 | L81: 16500 | M81: =+SUMIFS('[1]Annual fee sales'!$V:$V,'[1]Annual fee sales'!$L:$L,'Annual fee sales breakup - SAS'!$M$5,'[1]Annual fee sales'!$G:$G,'Annual fee sales breakup - SAS'!F81) | N81: =+SUMIFS('[1]Annual fee sales'!$V:$V,'[1]Annual fee sales'!$L:$L,'Annual fee sales breakup - SAS'!$N$5,'[1]Annual fee sales'!$G:$G,'Annual fee sales breakup - SAS'!F81) | O81: 0 | P81: 0 | Q81: =+L81-M81-N81-O81-P81
A82: =+A81+1 | B82: 46106 | C82: SAS BP | D82: SC260362 | E82: #N/A | F82: Kalle Shreenidhi | G82: SAS BP GRADE 3 MAGIC BOX GIRLS | I82: Grade 3 | L82: 16500 | M82: =+SUMIFS('[1]Annual fee sales'!$V:$V,'[1]Annual fee sales'!$L:$L,'Annual fee sales breakup - SAS'!$M$5,'[1]Annual fee sales'!$G:$G,'Annual fee sales breakup - SAS'!F82) | N82: =+SUMIFS('[1]Annual fee sales'!$V:$V,'[1]Annual fee sales'!$L:$L,'Annual fee sales breakup - SAS'!$N$5,'[1]Annual fee sales'!$G:$G,'Annual fee sales breakup - SAS'!F82) | O82: 0 | P82: 0 | Q82: =+L82-M82-N82-O82-P82
A83: =+A82+1 | B83: 46106 | C83: SAS BP | D83: SC260348 | E83: #N/A | F83: Vatte Raghava Reddy | G83: SAS BP GRADE 4 MAGIC BOX BOYS | I83: Grade 4 | L83: 19800 | M83: =+SUMIFS('[1]Annual fee sales'!$V:$V,'[1]Annual fee sales'!$L:$L,'Annual fee sales breakup - SAS'!$M$5,'[1]Annual fee sales'!$G:$G,'Annual fee sales breakup - SAS'!F83) | N83: =+SUMIFS('[1]Annual fee sales'!$V:$V,'[1]Annual fee sales'!$L:$L,'Annual fee sales breakup - SAS'!$N$5,'[1]Annual fee sales'!$G:$G,'Annual fee sales breakup - SAS'!F83) | O83: 0 | P83: 0 | Q83: =+L83-M83-N83-O83-P83
A84: =+A83+1 | B84: 46106 | C84: SAS BP | D84: SC260316 | E84: #N/A | F84: Bahulya Goud Kothinti | G84: SAS BP GRADE 4 MAGIC BOX BOYS | I84: Grade 4 | L84: 19800 | M84: =+SUMIFS('[1]Annual fee sales'!$V:$V,'[1]Annual fee sales'!$L:$L,'Annual fee sales breakup - SAS'!$M$5,'[1]Annual fee sales'!$G:$G,'Annual fee sales breakup - SAS'!F84) | N84: =+SUMIFS('[1]Annual fee sales'!$V:$V,'[1]Annual fee sales'!$L:$L,'Annual fee sales breakup - SAS'!$N$5,'[1]Annual fee sales'!$G:$G,'Annual fee sales breakup - SAS'!F84) | O84: 0 | P84: 0 | Q84: =+L84-M84-N84-O84-P84
A85: =+A84+1 | B85: 46106 | C85: SAS BP | D85: SC260226 | E85: #N/A | F85: Velisetty Aashrith Krishna | G85: SAS BP GRADE 4 MAGIC BOX BOYS | I85: Grade 4 | L85: 19800 | M85: =+SUMIFS('[1]Annual fee sales'!$V:$V,'[1]Annual fee sales'!$L:$L,'Annual fee sales breakup - SAS'!$M$5,'[1]Annual fee sales'!$G:$G,'Annual fee sales breakup - SAS'!F85) | N85: =+SUMIFS('[1]Annual fee sales'!$V:$V,'[1]Annual fee sales'!$L:$L,'Annual fee sales breakup - SAS'!$N$5,'[1]Annual fee sales'!$G:$G,'Annual fee sales breakup - SAS'!F85) | O85: 0 | P85: 0 | Q85: =+L85-M85-N85-O85-P85
A86: =+A85+1 | B86: 46106 | C86: SAS BP | D86: SC260120 | E86: #N/A | F86: Samaira Palanki | G86: SAS BP GRADE 4 MAGIC BOX GIRLS | I86: Grade 4 | L86: 19800 | M86: =+SUMIFS('[1]Annual fee sales'!$V:$V,'[1]Annual fee sales'!$L:$L,'Annual fee sales breakup - SAS'!$M$5,'[1]Annual fee sales'!$G:$G,'Annual fee sales breakup - SAS'!F86) | N86: =+SUMIFS('[1]Annual fee sales'!$V:$V,'[1]Annual fee sales'!$L:$L,'Annual fee sales breakup - SAS'!$N$5,'[1]Annual fee sales'!$G:$G,'Annual fee sales breakup - SAS'!F86) | O86: 0 | P86: 0 | Q86: =+L86-M86-N86-O86-P86
A87: =+A86+1 | B87: 46106 | C87: SAS BP | D87: SC260019 | E87: #N/A | F87: YASHITHA PAMU | G87: SAS BP GRADE 4 MAGIC BOX GIRLS | I87: Grade 4 | L87: 19800 | M87: =+SUMIFS('[1]Annual fee sales'!$V:$V,'[1]Annual fee sales'!$L:$L,'Annual fee sales breakup - SAS'!$M$5,'[1]Annual fee sales'!$G:$G,'Annual fee sales breakup - SAS'!F87) | N87: =+SUMIFS('[1]Annual fee sales'!$V:$V,'[1]Annual fee sales'!$L:$L,'Annual fee sales breakup - SAS'!$N$5,'[1]Annual fee sales'!$G:$G,'Annual fee sales breakup - SAS'!F87) | O87: 0 | P87: 0 | Q87: =+L87-M87-N87-O87-P87
A88: =+A87+1 | B88: 46106 | C88: SAS BP | D88: SC260300 | E88: #N/A | F88: Aadhya Thipparapu | G88: SAS BP GRADE 4 MAGIC BOX GIRLS | I88: Grade 4 | L88: 19800 | M88: =+SUMIFS('[1]Annual fee sales'!$V:$V,'[1]Annual fee sales'!$L:$L,'Annual fee sales breakup - SAS'!$M$5,'[1]Annual fee sales'!$G:$G,'Annual fee sales breakup - SAS'!F88) | N88: =+SUMIFS('[1]Annual fee sales'!$V:$V,'[1]Annual fee sales'!$L:$L,'Annual fee sales breakup - SAS'!$N$5,'[1]Annual fee sales'!$G:$G,'Annual fee sales breakup - SAS'!F88) | O88: 0 | P88: 0 | Q88: =+L88-M88-N88-O88-P88
A89: =+A88+1 | B89: 46106 | C89: SAS BP | D89: SC260189 | E89: #N/A | F89: Arra Venkat varun Reddy | G89: SAS BP GRADE 5 MAGIC BOX BOYS | I89: Grade 5 | L89: 19800 | M89: =+SUMIFS('[1]Annual fee sales'!$V:$V,'[1]Annual fee sales'!$L:$L,'Annual fee sales breakup - SAS'!$M$5,'[1]Annual fee sales'!$G:$G,'Annual fee sales breakup - SAS'!F89) | N89: =+SUMIFS('[1]Annual fee sales'!$V:$V,'[1]Annual fee sales'!$L:$L,'Annual fee sales breakup - SAS'!$N$5,'[1]Annual fee sales'!$G:$G,'Annual fee sales breakup - SAS'!F89) | O89: 0 | P89: 0 | Q89: =+L89-M89-N89-O89-P89
A90: =+A89+1 | B90: 46106 | C90: SAS BP | D90: SC260526 | E90: #N/A | F90: Simeon Shalom Chettupally | G90: SAS BP GRADE 5 MAGIC BOX BOYS | I90: Grade 5 | L90: 19800 | M90: =+SUMIFS('[1]Annual fee sales'!$V:$V,'[1]Annual fee sales'!$L:$L,'Annual fee sales breakup - SAS'!$M$5,'[1]Annual fee sales'!$G:$G,'Annual fee sales breakup - SAS'!F90) | N90: =+SUMIFS('[1]Annual fee sales'!$V:$V,'[1]Annual fee sales'!$L:$L,'Annual fee sales breakup - SAS'!$N$5,'[1]Annual fee sales'!$G:$G,'Annual fee sales breakup - SAS'!F90) | O90: 0 | P90: 0 | Q90: =+L90-M90-N90-O90-P90
A91: =+A90+1 | B91: 46106 | C91: SAS BP | D91: SC260194 | E91: #N/A | F91: Charvi Sai Vecham | G91: SAS BP GRADE 5 MAGIC BOX GIRLS | I91: Grade 5 | L91: 19800 | M91: =+SUMIFS('[1]Annual fee sales'!$V:$V,'[1]Annual fee sales'!$L:$L,'Annual fee sales breakup - SAS'!$M$5,'[1]Annual fee sales'!$G:$G,'Annual fee sales breakup - SAS'!F91) | N91: =+SUMIFS('[1]Annual fee sales'!$V:$V,'[1]Annual fee sales'!$L:$L,'Annual fee sales breakup - SAS'!$N$5,'[1]Annual fee sales'!$G:$G,'Annual fee sales breakup - SAS'!F91) | O91: 0 | P91: 0 | Q91: =+L91-M91-N91-O91-P91
A92: =+A91+1 | B92: 46106 | C92: SAS BP | D92: 26BP0523 | E92: #N/A | F92: SANVI SARISA | G92: SAS BP GRADE 5 MAGIC BOX GIRLS | I92: Grade 5 | L92: 19800 | M92: =+SUMIFS('[1]Annual fee sales'!$V:$V,'[1]Annual fee sales'!$L:$L,'Annual fee sales breakup - SAS'!$M$5,'[1]Annual fee sales'!$G:$G,'Annual fee sales breakup - SAS'!F92) | N92: =+SUMIFS('[1]Annual fee sales'!$V:$V,'[1]Annual fee sales'!$L:$L,'Annual fee sales breakup - SAS'!$N$5,'[1]Annual fee sales'!$G:$G,'Annual fee sales breakup - SAS'!F92) | O92: 0 | P92: 0 | Q92: =+L92-M92-N92-O92-P92
... A96: =+A95+1 | B96: 46106 | C96: SAS BP | D96: SC260018 | E96: #N/A | F96: SAHASRA PAMU - 1 | G96: SAS BP GRADE 6 MAGIC BOX GIRLS | I96: Grade 6 | L96: 22000 | M96: =+SUMIFS('[1]Annual fee sales'!$V:$V,'[1]Annual fee sales'!$L:$L,'Annual fee sales breakup - SAS'!$M$5,'[1]Annual fee sales'!$G:$G,'Annual fee sales breakup - SAS'!F96) | N96: =+SUMIFS('[1]Annual fee sales'!$V:$V,'[1]Annual fee sales'!$L:$L,'Annual fee sales breakup - SAS'!$N$5,'[1]Annual fee sales'!$G:$G,'Annual fee sales breakup - SAS'!F96) | O96: 0 | P96: 0 | Q96: =+L96-M96-N96-O96-P96
A97: =+A96+1 | B97: 46106 | C97: SAS BP | D97: SC260028 | E97: Delivered | F97: SUHAS REDDY KOTA - 1 | G97: SAS BP GRADE 7 MAGIC BOX BOYS | H97: SAS Suchitra Grade 7 BookkitHindi 2nd Lan Tel 3rd Lan | I97: Grade 7 | L97: 22000 | M97: =+SUMIFS('[1]Annual fee sales'!$V:$V,'[1]Annual fee sales'!$L:$L,'Annual fee sales breakup - SAS'!$M$5,'[1]Annual fee sales'!$G:$G,'Annual fee sales breakup - SAS'!F97) | N97: =+SUMIFS('[1]Annual fee sales'!$V:$V,'[1]Annual fee sales'!$L:$L,'Annual fee sales breakup - SAS'!$N$5,'[1]Annual fee sales'!$G:$G,'Annual fee sales breakup - SAS'!F97) | O97: 9411.5 | P97: 0 | Q97: =+L97-M97-N97-O97-P97
A98: =+A97+1 | B98: 46106 | C98: SAS BP | D98: SC260006 | E98: #N/A | F98: Thumma Sushanth Reddy | G98: SAS BP GRADE 7 MAGIC BOX BOYS | I98: Grade 7 | L98: 22000 | M98: =+SUMIFS('[1]Annual fee sales'!$V:$V,'[1]Annual fee sales'!$L:$L,'Annual fee sales breakup - SAS'!$M$5,'[1]Annual fee sales'!$G:$G,'Annual fee sales breakup - SAS'!F98) | N98: =+SUMIFS('[1]Annual fee sales'!$V:$V,'[1]Annual fee sales'!$L:$L,'Annual fee sales breakup - SAS'!$N$5,'[1]Annual fee sales'!$G:$G,'Annual fee sales breakup - SAS'!F98) | O98: 0 | P98: 0 | Q98: =+L98-M98-N98-O98-P98
A99: =+A98+1 | B99: 46106 | C99: SAS BP | D99: SC260361 | E99: Delivered | F99: Siva Mohit Reddy Satti | G99: SAS BP GRADE 7 MAGIC BOX BOYS | H99: SAS Suchitra Grade 7 BookkitTelugu 2nd Lan Hin 3rd Lan | I99: Grade 7 | L99: 22000 | M99: =+SUMIFS('[1]Annual fee sales'!$V:$V,'[1]Annual fee sales'!$L:$L,'Annual fee sales breakup - SAS'!$M$5,'[1]Annual fee sales'!$G:$G,'Annual fee sales breakup - SAS'!F99) | N99: =+SUMIFS('[1]Annual fee sales'!$V:$V,'[1]Annual fee sales'!$L:$L,'Annual fee sales breakup - SAS'!$N$5,'[1]Annual fee sales'!$G:$G,'Annual fee sales breakup - SAS'!F99) | O99: 9061.5 | P99: 0 | Q99: =+L99-M99-N99-O99-P99
A100: =+A99+1 | B100: 46106 | C100: SAS BP | D100: SC260175 | E100: Delivered | F100: Aarvi Prashant Konda | G100: SAS BP GRADE 7 MAGIC BOX GIRLS | H100: SAS Suchitra Grade 7 BookkitHindi 2nd Lan Tel 3rd Lan | I100: Grade 7 | L100: 22000 | M100: =+SUMIFS('[1]Annual fee sales'!$V:$V,'[1]Annual fee sales'!$L:$L,'Annual fee sales breakup - SAS'!$M$5,'[1]Annual fee sales'!$G:$G,'Annual fee sales breakup - SAS'!F100) | N100: =+SUMIFS('[1]Annual fee sales'!$V:$V,'[1]Annual fee sales'!$L:$L,'Annual fee sales breakup - SAS'!$N$5,'[1]Annual fee sales'!$G:$G,'Annual fee sales breakup - SAS'!F100) | O100: 9411.5 | P100: 0 | Q100: =+L100-M100-N100-O100-P100
A101: =+A100+1 | B101: 46106 | C101: SAS BP | D101: SC260165 | E101: Delivered | F101: Anvitha Bitla | G101: SAS BP GRADE 7 MAGIC BOX GIRLS | H101: SAS Suchitra Grade 7 BookkitTelugu 2nd Lan Hin 3rd Lan | I101: Grade 7 | L101: 22000 | M101: =+SUMIFS('[1]Annual fee sales'!$V:$V,'[1]Annual fee sales'!$L:$L,'Annual fee sales breakup - SAS'!$M$5,'[1]Annual fee sales'!$G:$G,'Annual fee sales breakup - SAS'!F101) | N101: =+SUMIFS('[1]Annual fee sales'!$V:$V,'[1]Annual fee sales'!$L:$L,'Annual fee sales breakup - SAS'!$N$5,'[1]Annual fee sales'!$G:$G,'Annual fee sales breakup - SAS'!F101) | O101: 9061.5 | P101: 0 | Q101: =+L101-M101-N101-O101-P101
A102: =+A101+1 | B102: 46106 | C102: SAS BP | D102: 26BP0594 | E102: Delivered | F102: Varenya Kunapuli | G102: SAS BP GRADE 7 MAGIC BOX GIRLS | H102: SAS Suchitra Grade 7 BookkitHindi 2nd Lan Tel 3rd Lan | I102: Grade 7 | L102: 22000 | M102: =+SUMIFS('[1]Annual fee sales'!$V:$V,'[1]Annual fee sales'!$L:$L,'Annual fee sales breakup - SAS'!$M$5,'[1]Annual fee sales'!$G:$G,'Annual fee sales breakup - SAS'!F102) | N102: =+SUMIFS('[1]Annual fee sales'!$V:$V,'[1]Annual fee sales'!$L:$L,'Annual fee sales breakup - SAS'!$N$5,'[1]Annual fee sales'!$G:$G,'Annual fee sales breakup - SAS'!F102) | O102: 9411.5 | P102: 0 | Q102: =+L102-M102-N102-O102-P102
A103: =+A102+1 | B103: 46106 | C103: SAS BP | D103: SC260338 | E103: #N/A | F103: Nimmala Varshith kumar | G103: SAS BP GRADE 8 MAGIC BOX BOYS | I103: Grade 8 | L103: 22000 | M103: =+SUMIFS('[1]Annual fee sales'!$V:$V,'[1]Annual fee sales'!$L:$L,'Annual fee sales breakup - SAS'!$M$5,'[1]Annual fee sales'!$G:$G,'Annual fee sales breakup - SAS'!F103) | N103: =+SUMIFS('[1]Annual fee sales'!$V:$V,'[1]Annual fee sales'!$L:$L,'Annual fee sales breakup - SAS'!$N$5,'[1]Annual fee sales'!$G:$G,'Annual fee sales breakup - SAS'!F103) | O103: 0 | P103: 0 | Q103: =+L103-M103-N103-O103-P103
...

Sheet SMS
A1: S.No | B1: Receipt Date | C1: School Name | D1: Enrollment NO | E1: Delivery status | F1: Student Name | G1: Description | H1: Language of Book | I1: Grade | J1: Receipt No | K1: Fee Type | L1: Total
A2: 1 | B2: 46098 | C2: SAS BP | D2: SC260407 | E2: #N/A | F2: Ivan Prince | G2: SAS BP LKG MAGIC BOX BOYS | I2: LKG | L2: 11000
A3: 2 | B3: 46098 | C3: SAS BP | D3: SC260267 | E3: #N/A | F3: Devansh Yadav Addu | G3: SAS BP LKG MAGIC BOX BOYS | I3: LKG | L3: 11000
A4: 3 | B4: 46098 | C4: SAS BP | D4: 26BP0558 | E4: #N/A | F4: DANDA ADHVITHA REDDY | G4: SAS BP LKG MAGIC BOX GIRLS | I4: LKG | L4: 11000
A5: 4 | B5: 46098 | C5: SAS BP | D5: SC260076 | E5: #N/A | F5: Yuvika Reddy Musani | G5: SAS BP UKG MAGIC BOX GIRLS | I5: UKG | L5: 11000
A6: 5 | B6: 46099 | C6: SAS BP | D6: SC260174 | E6: #N/A | F6: Eavanshi Bommala | G6: SAS BP LKG MAGIC BOX GIRLS | I6: LKG | L6: 11000
A7: 6 | B7: 46099 | C7: SAS BP | D7: SC260132 | E7: #N/A | F7: Shreya L S | G7: SAS BP NURSERY MAGIC BOX GIRLS | I7: Nursery | L7: 11000
A8: 7 | B8: 46099 | C8: SAS BP | D8: SC260092 | E8: #N/A | F8: Sushrut Saleel Limaye | G8: SAS BP UKG MAGIC BOX BOYS | I8: UKG | L8: 11000
A9: 8 | B9: 46099 | C9: SAS BP | D9: SC260145 | E9: #N/A | F9: Atharv Garipally | G9: SAS BP UKG MAGIC BOX BOYS | I9: UKG | L9: 11000
A10: 9 | B10: 46099 | C10: SAS BP | D10: SC260081 | E10: #N/A | F10: Purvansh Nelly | G10: SAS BP UKG MAGIC BOX BOYS | I10: UKG | L10: 11000
A11: 10 | B11: 46100 | C11: SAS BP | D11: SC260122 | E11: #N/A | F11: Hanzala Arham Mohammad - 1 | G11: SAS BP GRADE 1 MAGIC BOX BOYS | I11: Grade 1 | L11: 16500
A12: 11 | B12: 46100 | C12: SAS BP | D12: 26BP0532 | E12: #N/A | F12: RIYANSH DIGIJARLA | G12: SAS BP GRADE 1 MAGIC BOX BOYS | I12: Grade 1 | L12: 16500
A13: 12 | B13: 46100 | C13: SAS BP | D13: SC260147 | E13: #N/A | F13: Kopparapu Sri Dhruti | G13: SAS BP GRADE 1 MAGIC BOX GIRLS | I13: Grade 1 | L13: 16500
... A75: 74 | B75: 46106 | C75: SAS BP | D75: SC260470 | E75: #N/A | F75: Nivaan Varma | G75: SAS BP GRADE 3 MAGIC BOX BOYS | I75: Grade 3 | L75: 16500
A76: 75 | B76: 46106 | C76: SAS BP | D76: SC260059 | E76: Delivered | F76: Ashrith Ranga Reddy Panyala | G76: SAS BP GRADE 3 MAGIC BOX BOYS | H76: SAS Suchitra Grade 3 BookkitTelugu 2nd Lan Hin 3rd Lan | I76: Grade 3 | L76: 16500
A77: 76 | B77: 46106 | C77: SAS BP | D77: SC260062 | E77: #N/A | F77: Sanjay Peram - 1 | G77: SAS BP GRADE 3 MAGIC BOX BOYS | I77: Grade 3 | L77: 16500
A78: 77 | B78: 46106 | C78: SAS BP | D78: SC260362 | E78: #N/A | F78: Kalle Shreenidhi | G78: SAS BP GRADE 3 MAGIC BOX GIRLS | I78: Grade 3 | L78: 16500
A79: 78 | B79: 46106 | C79: SAS BP | D79: SC260348 | E79: #N/A | F79: Vatte Raghava Reddy | G79: SAS BP GRADE 4 MAGIC BOX BOYS | I79: Grade 4 | L79: 19800
A80: 79 | B80: 46106 | C80: SAS BP | D80: SC260316 | E80: #N/A | F80: Bahulya Goud Kothinti | G80: SAS BP GRADE 4 MAGIC BOX BOYS | I80: Grade 4 | L80: 19800
A81: 80 | B81: 46106 | C81: SAS BP | D81: SC260226 | E81: #N/A | F81: Velisetty Aashrith Krishna | G81: SAS BP GRADE 4 MAGIC BOX BOYS | I81: Grade 4 | L81: 19800
A82: 81 | B82: 46106 | C82: SAS BP | D82: SC260120 | E82: #N/A | F82: Samaira Palanki | G82: SAS BP GRADE 4 MAGIC BOX GIRLS | I82: Grade 4 | L82: 19800
A83: 82 | B83: 46106 | C83: SAS BP | D83: SC260019 | E83: #N/A | F83: YASHITHA PAMU | G83: SAS BP GRADE 4 MAGIC BOX GIRLS | I83: Grade 4 | L83: 19800
A84: 83 | B84: 46106 | C84: SAS BP | D84: SC260300 | E84: #N/A | F84: Aadhya Thipparapu | G84: SAS BP GRADE 4 MAGIC BOX GIRLS | I84: Grade 4 | L84: 19800
A85: 84 | B85: 46106 | C85: SAS BP | D85: SC260189 | E85: #N/A | F85: Arra Venkat varun Reddy | G85: SAS BP GRADE 5 MAGIC BOX BOYS | I85: Grade 5 | L85: 19800
A86: 85 | B86: 46106 | C86: SAS BP | D86: SC260526 | E86: #N/A | F86: Simeon Shalom Chettupally | G86: SAS BP GRADE 5 MAGIC BOX BOYS | I86: Grade 5 | L86: 19800
A87: 86 | B87: 46106 | C87: SAS BP | D87: SC260194 | E87: #N/A | F87: Charvi Sai Vecham | G87: SAS BP GRADE 5 MAGIC BOX GIRLS | I87: Grade 5 | L87: 19800
A88: 87 | B88: 46106 | C88: SAS BP | D88: 26BP0523 | E88: #N/A | F88: SANVI SARISA | G88: SAS BP GRADE 5 MAGIC BOX GIRLS | I88: Grade 5 | L88: 19800
... A92: 91 | B92: 46106 | C92: SAS BP | D92: SC260018 | E92: #N/A | F92: SAHASRA PAMU - 1 | G92: SAS BP GRADE 6 MAGIC BOX GIRLS | I92: Grade 6 | L92: 22000
A93: 92 | B93: 46106 | C93: SAS BP | D93: SC260028 | E93: Delivered | F93: SUHAS REDDY KOTA - 1 | G93: SAS BP GRADE 7 MAGIC BOX BOYS | H93: SAS Suchitra Grade 7 BookkitHindi 2nd Lan Tel 3rd Lan | I93: Grade 7 | L93: 22000
A94: 93 | B94: 46106 | C94: SAS BP | D94: SC260006 | E94: #N/A | F94: Thumma Sushanth Reddy | G94: SAS BP GRADE 7 MAGIC BOX BOYS | I94: Grade 7 | L94: 22000
A95: 94 | B95: 46106 | C95: SAS BP | D95: SC260361 | E95: Delivered | F95: Siva Mohit Reddy Satti | G95: SAS BP GRADE 7 MAGIC BOX BOYS | H95: SAS Suchitra Grade 7 BookkitTelugu 2nd Lan Hin 3rd Lan | I95: Grade 7 | L95: 22000
A96: 95 | B96: 46106 | C96: SAS BP | D96: SC260175 | E96: Delivered | F96: Aarvi Prashant Konda | G96: SAS BP GRADE 7 MAGIC BOX GIRLS | H96: SAS Suchitra Grade 7 BookkitHindi 2nd Lan Tel 3rd Lan | I96: Grade 7 | L96: 22000
A97: 96 | B97: 46106 | C97: SAS BP | D97: SC260165 | E97: Delivered | F97: Anvitha Bitla | G97: SAS BP GRADE 7 MAGIC BOX GIRLS | H97: SAS Suchitra Grade 7 BookkitTelugu 2nd Lan Hin 3rd Lan | I97: Grade 7 | L97: 22000
A98: 97 | B98: 46106 | C98: SAS BP | D98: 26BP0594 | E98: Delivered | F98: Varenya Kunapuli | G98: SAS BP GRADE 7 MAGIC BOX GIRLS | H98: SAS Suchitra Grade 7 BookkitHindi 2nd Lan Tel 3rd Lan | I98: Grade 7 | L98: 22000
A99: 98 | B99: 46106 | C99: SAS BP | D99: SC260338 | E99: #N/A | F99: Nimmala Varshith kumar | G99: SAS BP GRADE 8 MAGIC BOX BOYS | I99: Grade 8 | L99: 22000
A100: 99 | B100: 46106 | C100: SAS BP | D100: SC260037 | E100: Delivered | F100: VENKATA HANSITH MADDURI | G100: SAS BP GRADE 8 MAGIC BOX BOYS | H100: SAS Suchitra Grade 8 BookkitTelugu 2nd Lan Hin 3rd Lan | I100: Grade 8 | L100: 22000
A101: 100 | B101: 46106 | C101: SAS BP | D101: 26BP0550 | E101: #N/A | F101: KURAPATI ABHIRAM ABHIRAM | G101: SAS BP GRADE 8 MAGIC BOX BOYS | I101: Grade 8 | L101: 22000
A102: 101 | B102: 46106 | C102: SAS BP | D102: SC260061 | E102: #N/A | F102: Samrithi Reddy Chettypalli | G102: SAS BP GRADE 8 MAGIC BOX GIRLS | I102: Grade 8 | L102: 22000
A103: 102 | B103: 46106 | C103: SAS BP | D103: SC260312 | E103: #N/A | F103: Joan Shiju - 1 | G103: SAS BP GRADE 8 MAGIC BOX GIRLS | I103: Grade 8 | L103: 22000
A104: 103 | B104: 46106 | C104: SAS BP | D104: SC260289 | E104: #N/A | F104: Yeshwasri Annm | G104: SAS BP GRADE 8 MAGIC BOX GIRLS | I104: Grade 8 | L104: 22000
...
